<?xml version="1.0" encoding="UTF-8"?>
<!-- Generated by org.testng.reporters.JUnitXMLReporter -->
<testsuite hostname="SAMINCHANA" ignored="1" name="Default test(failed)" tests="4" failures="1" timestamp="2019-11-28T10:09:27 IST" time="0.082" errors="0">
  <testcase name="Test1" time="0.015" classname="SecondMavenProject.SecondMavenProject.RetryFailedTestCases">
    <skipped/>
  </testcase> <!-- Test1 -->
  <testcase name="Test1" time="0.002" classname="SecondMavenProject.SecondMavenProject.RetryFailedTestCases">
    <skipped/>
  </testcase> <!-- Test1 -->
  <testcase name="Test1" time="0.002" classname="SecondMavenProject.SecondMavenProject.RetryFailedTestCases">
    <skipped/>
  </testcase> <!-- Test1 -->
  <testcase name="Test1" time="0.001" classname="SecondMavenProject.SecondMavenProject.RetryFailedTestCases">
    <failure type="java.lang.AssertionError" message="expected [false] but found [true]">
      <![CDATA[java.lang.AssertionError: expected [false] but found [true]
at SecondMavenProject.SecondMavenProject.RetryFailedTestCases.Test1(RetryFailedTestCases.java:12)
at java.util.ArrayList.forEach(Unknown Source)
... Removed 32 stack frames]]>
    </failure>
  </testcase> <!-- Test1 -->
  <testcase name="Test2" time="0.0" classname="SecondMavenProject.SecondMavenProject.RetryFailedTestCases">
    <ignored/>
  </testcase> <!-- Test2 -->
</testsuite> <!-- Default test(failed) -->
