<?xml version="1.0" encoding="UTF-8"?>
<!-- Generated by org.testng.reporters.JUnitXMLReporter -->
<testsuite hostname="SAMINCHANA" ignored="0" name="Functional Test" tests="9" failures="1" timestamp="2019-11-30T19:19:37 IST" time="0.086" errors="0">
  <testcase name="Test5" time="0.006" classname="SecondMavenProject.SecondMavenProject.Annotations"/>
  <testcase name="test4" time="0.012" classname="SecondMavenProject.SecondMavenProject.DependsOnMethodTest"/>
  <testcase name="Test6" time="0.008" classname="SecondMavenProject.SecondMavenProject.Annotations"/>
  <testcase name="Test7" time="0.011" classname="SecondMavenProject.SecondMavenProject.Annotations"/>
  <testcase name="test1" time="0.015" classname="SecondMavenProject.SecondMavenProject.DependsOnMethodTest"/>
  <testcase name="test6" time="0.002" classname="SecondMavenProject.SecondMavenProject.DependsOnMethodTest"/>
  <testcase name="test5" time="0.002" classname="SecondMavenProject.SecondMavenProject.DependsOnMethodTest"/>
  <testcase name="test2" time="0.006" classname="SecondMavenProject.SecondMavenProject.DependsOnMethodTest">
    <failure type="java.lang.AssertionError" message="did not expect to find [true] but found [false]">
      <![CDATA[java.lang.AssertionError: did not expect to find [true] but found [false]
at SecondMavenProject.SecondMavenProject.DependsOnMethodTest.test2(DependsOnMethodTest.java:15)
at java.util.concurrent.ThreadPoolExecutor.runWorker(ThreadPoolExecutor.java:1149)
at java.util.concurrent.ThreadPoolExecutor$Worker.run(ThreadPoolExecutor.java:624)
at java.lang.Thread.run(Thread.java:748)
... Removed 16 stack frames]]>
    </failure>
  </testcase> <!-- test2 -->
  <testcase name="test3" time="0.0" classname="SecondMavenProject.SecondMavenProject.DependsOnMethodTest">
    <skipped/>
  </testcase> <!-- test3 -->
</testsuite> <!-- Functional Test -->
